<sdf version='1.7'>
  <model name='robotiq85_gripper'>
    <link name='robotiq_coupler_link'>
      <inertial>
        <pose>0 0 -0.044123 0 -0 0</pose>
        <mass>0.736951</mass>
        <inertia>
          <ixx>0.00133625</ixx>
          <ixy>3.73517e-21</ixy>
          <ixz>2.96577e-36</ixz>
          <iyy>0.00139725</iyy>
          <iyz>4.84348e-20</iyz>
          <izz>0.000381</izz>
        </inertia>
      </inertial>
      <collision name='robotiq_coupler_link_collision'>
        <pose>0 0 0 0 -0 0</pose>
        <geometry>
          <mesh>
            <scale>1 1 1</scale>
            <uri>model://movo_description/meshes/manipulation/robotiq/collision/kinova_robotiq_coupler.obj</uri>
          </mesh>
        </geometry>
      </collision>
      <collision name='robotiq_coupler_link_fixed_joint_lump__gripper_base_link_collision_1'>
        <pose>0 0 -0.05105 -1.5708 1.5708 0</pose>
        <geometry>
          <mesh>
            <scale>1 1 1</scale>
            <uri>model://movo_description/meshes/manipulation/robotiq/collision/robotiq_85_base_link.obj</uri>
          </mesh>
        </geometry>
      </collision>
      <visual name='robotiq_coupler_link_visual'>
        <pose>0 0 0 0 -0 0</pose>
        <geometry>
          <mesh>
            <scale>1 1 1</scale>
            <uri>model://movo_description/meshes/manipulation/robotiq/visual/kinova_robotiq_coupler.obj</uri>
          </mesh>
        </geometry>
      </visual>
      <visual name='robotiq_coupler_link_fixed_joint_lump__gripper_base_link_visual_1'>
        <pose>0 0 -0.05105 -1.5708 1.5708 0</pose>
        <geometry>
          <mesh>
            <scale>1 1 1</scale>
            <uri>model://movo_description/meshes/manipulation/robotiq/visual/robotiq_85_base_link.obj</uri>
          </mesh>
        </geometry>
      </visual>
    </link>
    <joint name='gripper_finger1_inner_knuckle_joint' type='revolute'>
      <pose relative_to='robotiq_coupler_link'>-0.0127 0 -0.11247 1.57079 1.57079 0</pose>
      <parent>robotiq_coupler_link</parent>
      <child>gripper_finger1_inner_knuckle_link</child>
      <axis>
        <xyz>0 0 1</xyz>
        <limit>
          <lower>-3.14</lower>
          <upper>3.14</upper>
          <effort>0.1</effort>
          <velocity>100</velocity>
        </limit>
        <dynamics>
          <spring_reference>0</spring_reference>
          <spring_stiffness>0</spring_stiffness>
        </dynamics>
      </axis>
    </joint>
    <link name='gripper_finger1_inner_knuckle_link'>
      <pose relative_to='gripper_finger1_inner_knuckle_joint'>0 0 0 0 -0 0</pose>
      <inertial>
        <pose>0 0 0 0 -0 0</pose>
        <mass>0.029951</mass>
        <inertia>
          <ixx>3.9e-05</ixx>
          <ixy>0</ixy>
          <ixz>0</ixz>
          <iyy>5e-06</iyy>
          <iyz>0</iyz>
          <izz>3.5e-05</izz>
        </inertia>
      </inertial>
      <visual name='gripper_finger1_inner_knuckle_link_visual'>
        <pose>0 0 0 0 -0 0</pose>
        <geometry>
          <mesh>
            <scale>1 1 1</scale>
            <uri>model://movo_description/meshes/manipulation/robotiq/visual/robotiq_85_inner_knuckle_link.obj</uri>
          </mesh>
        </geometry>
      </visual>
    </link>
    <joint name='gripper_finger1_finger_tip_joint' type='revolute'>
      <pose relative_to='gripper_finger1_inner_knuckle_link'>0.04304 -0.037599 0 0 -0 0</pose>
      <parent>gripper_finger1_inner_knuckle_link</parent>
      <child>gripper_finger1_finger_tip_link</child>
      <axis>
        <xyz>0 0 1</xyz>
        <limit>
          <lower>-3.14</lower>
          <upper>3.14</upper>
          <effort>0.1</effort>
          <velocity>100</velocity>
        </limit>
        <dynamics>
          <spring_reference>0</spring_reference>
          <spring_stiffness>0</spring_stiffness>
        </dynamics>
      </axis>
    </joint>
    <link name='gripper_finger1_finger_tip_link'>
      <pose relative_to='gripper_finger1_finger_tip_joint'>0 0 0 0 -0 0</pose>
      <inertial>
        <pose>0 0 0 0 -0 0</pose>
        <mass>0.019555</mass>
        <inertia>
          <ixx>2e-06</ixx>
          <ixy>0</ixy>
          <ixz>0</ixz>
          <iyy>5e-06</iyy>
          <iyz>0</iyz>
          <izz>6e-06</izz>
        </inertia>
      </inertial>
      <collision name='gripper_finger1_finger_tip_link_collision'>
        <pose>0.02575 0.004375 0 0 -0 0</pose>
        <geometry>
          <box>
            <size>0.0375 0.00675 0.022</size>
          </box>
        </geometry>
      </collision>
      <visual name='gripper_finger1_finger_tip_link_visual'>
        <pose>0 0 0 0 -0 0</pose>
        <geometry>
          <mesh>
            <scale>1 1 1</scale>
            <uri>model://movo_description/meshes/manipulation/robotiq/visual/robotiq_85_finger_tip_link.obj</uri>
          </mesh>
        </geometry>
      </visual>
    </link>
    <joint name='gripper_finger1_joint' type='revolute'>
      <pose relative_to='robotiq_coupler_link'>-0.030601 0 -0.105955 1.57079 1.57079 0</pose>
      <parent>robotiq_coupler_link</parent>
      <child>gripper_finger1_knuckle_link</child>
      <axis>
        <xyz>0 0 1</xyz>
        <limit>
          <lower>0</lower>
          <upper>0.804</upper>
          <effort>1000</effort>
          <velocity>2</velocity>
        </limit>
        <dynamics>
          <spring_reference>0</spring_reference>
          <spring_stiffness>0</spring_stiffness>
        </dynamics>
      </axis>
    </joint>
    <link name='gripper_finger1_knuckle_link'>
      <pose relative_to='gripper_finger1_joint'>0 0 0 0 -0 0</pose>
      <inertial>
        <pose>-0.002436 -0.018774 0 0 -0 0</pose>
        <mass>0.0458</mass>
        <inertia>
          <ixx>2.29304e-05</ixx>
          <ixy>-4.4183e-06</ixy>
          <ixz>0</ixz>
          <iyy>2.2184e-05</iyy>
          <iyz>0</iyz>
          <izz>4.11145e-05</izz>
        </inertia>
      </inertial>
      <collision name='gripper_finger1_knuckle_link_collision'>
        <pose>0 0 0 0 -0 0</pose>
        <geometry>
          <mesh>
            <scale>1 1 1</scale>
            <uri>model://movo_description/meshes/manipulation/robotiq/collision/robotiq_85_knuckle_link.obj</uri>
          </mesh>
        </geometry>
      </collision>
      <collision name='gripper_finger1_knuckle_link_fixed_joint_lump__gripper_finger1_finger_link_collision_1'>
        <pose>-0.004086 -0.031486 0 0 -0 0</pose>
        <geometry>
          <mesh>
            <scale>1 1 1</scale>
            <uri>model://movo_description/meshes/manipulation/robotiq/collision/robotiq_85_finger_link.obj</uri>
          </mesh>
        </geometry>
      </collision>
      <visual name='gripper_finger1_knuckle_link_visual'>
        <pose>0 0 0 0 -0 0</pose>
        <geometry>
          <mesh>
            <scale>1 1 1</scale>
            <uri>model://movo_description/meshes/manipulation/robotiq/visual/robotiq_85_knuckle_link.obj</uri>
          </mesh>
        </geometry>
      </visual>
      <visual name='gripper_finger1_knuckle_link_fixed_joint_lump__gripper_finger1_finger_link_visual_1'>
        <pose>-0.004086 -0.031486 0 0 -0 0</pose>
        <geometry>
          <mesh>
            <scale>1 1 1</scale>
            <uri>model://movo_description/meshes/manipulation/robotiq/visual/robotiq_85_finger_link.obj</uri>
          </mesh>
        </geometry>
      </visual>
    </link>
    <joint name='gripper_finger2_inner_knuckle_joint' type='revolute'>
      <pose relative_to='robotiq_coupler_link'>0.0127 -0 -0.11247 -1.57079 1.57079 0</pose>
      <parent>robotiq_coupler_link</parent>
      <child>gripper_finger2_inner_knuckle_link</child>
      <axis>
        <xyz>0 0 1</xyz>
        <limit>
          <lower>-3.14</lower>
          <upper>3.14</upper>
          <effort>0.1</effort>
          <velocity>100</velocity>
        </limit>
        <dynamics>
          <spring_reference>0</spring_reference>
          <spring_stiffness>0</spring_stiffness>
        </dynamics>
      </axis>
    </joint>
    <link name='gripper_finger2_inner_knuckle_link'>
      <pose relative_to='gripper_finger2_inner_knuckle_joint'>0 0 0 0 -0 0</pose>
      <inertial>
        <pose>0 0 0 0 -0 0</pose>
        <mass>0.029951</mass>
        <inertia>
          <ixx>3.9e-05</ixx>
          <ixy>0</ixy>
          <ixz>0</ixz>
          <iyy>5e-06</iyy>
          <iyz>0</iyz>
          <izz>3.5e-05</izz>
        </inertia>
      </inertial>
      <visual name='gripper_finger2_inner_knuckle_link_visual'>
        <pose>0 0 0 0 -0 0</pose>
        <geometry>
          <mesh>
            <scale>1 1 1</scale>
            <uri>model://movo_description/meshes/manipulation/robotiq/visual/robotiq_85_inner_knuckle_link.obj</uri>
          </mesh>
        </geometry>
      </visual>
    </link>
    <joint name='gripper_finger2_finger_tip_joint' type='revolute'>
      <pose relative_to='gripper_finger2_inner_knuckle_link'>0.04304 -0.037599 0 0 -0 0</pose>
      <parent>gripper_finger2_inner_knuckle_link</parent>
      <child>gripper_finger2_finger_tip_link</child>
      <axis>
        <xyz>0 0 1</xyz>
        <limit>
          <lower>-3.14</lower>
          <upper>3.14</upper>
          <effort>0.1</effort>
          <velocity>100</velocity>
        </limit>
        <dynamics>
          <spring_reference>0</spring_reference>
          <spring_stiffness>0</spring_stiffness>
        </dynamics>
      </axis>
    </joint>
    <link name='gripper_finger2_finger_tip_link'>
      <pose relative_to='gripper_finger2_finger_tip_joint'>0 0 0 0 -0 0</pose>
      <inertial>
        <pose>0 0 0 0 -0 0</pose>
        <mass>0.019555</mass>
        <inertia>
          <ixx>2e-06</ixx>
          <ixy>0</ixy>
          <ixz>0</ixz>
          <iyy>5e-06</iyy>
          <iyz>0</iyz>
          <izz>6e-06</izz>
        </inertia>
      </inertial>
      <collision name='gripper_finger2_finger_tip_link_collision'>
        <pose>0.02575 0.004375 0 0 -0 0</pose>
        <geometry>
          <box>
            <size>0.0375 0.00675 0.022</size>
          </box>
        </geometry>
      </collision>
      <visual name='gripper_finger2_finger_tip_link_visual'>
        <pose>0 0 0 0 -0 0</pose>
        <geometry>
          <mesh>
            <scale>1 1 1</scale>
            <uri>model://movo_description/meshes/manipulation/robotiq/visual/robotiq_85_finger_tip_link.obj</uri>
          </mesh>
        </geometry>
      </visual>
    </link>
    <joint name='gripper_finger2_joint' type='revolute'>
      <pose relative_to='robotiq_coupler_link'>0.030601 -0 -0.105954 -1.57079 1.57079 0</pose>
      <parent>robotiq_coupler_link</parent>
      <child>gripper_finger2_knuckle_link</child>
      <axis>
        <xyz>0 0 1</xyz>
        <limit>
          <lower>-3.14</lower>
          <upper>3.14</upper>
          <effort>1000</effort>
          <velocity>100</velocity>
        </limit>
        <dynamics>
          <spring_reference>0</spring_reference>
          <spring_stiffness>0</spring_stiffness>
        </dynamics>
      </axis>
    </joint>
    <link name='gripper_finger2_knuckle_link'>
      <pose relative_to='gripper_finger2_joint'>0 0 0 0 -0 0</pose>
      <inertial>
        <pose>-0.002436 -0.018774 0 0 -0 0</pose>
        <mass>0.0458</mass>
        <inertia>
          <ixx>2.29304e-05</ixx>
          <ixy>-4.4183e-06</ixy>
          <ixz>0</ixz>
          <iyy>2.2184e-05</iyy>
          <iyz>0</iyz>
          <izz>4.11145e-05</izz>
        </inertia>
      </inertial>
      <collision name='gripper_finger2_knuckle_link_collision'>
        <pose>0 0 0 0 -0 0</pose>
        <geometry>
          <mesh>
            <scale>1 1 1</scale>
            <uri>model://movo_description/meshes/manipulation/robotiq/collision/robotiq_85_knuckle_link.obj</uri>
          </mesh>
        </geometry>
      </collision>
      <collision name='gripper_finger2_knuckle_link_fixed_joint_lump__gripper_finger2_finger_link_collision_1'>
        <pose>-0.004086 -0.031486 0 0 -0 0</pose>
        <geometry>
          <mesh>
            <scale>1 1 1</scale>
            <uri>model://movo_description/meshes/manipulation/robotiq/collision/robotiq_85_finger_link.obj</uri>
          </mesh>
        </geometry>
      </collision>
      <visual name='gripper_finger2_knuckle_link_visual'>
        <pose>0 0 0 0 -0 0</pose>
        <geometry>
          <mesh>
            <scale>1 1 1</scale>
            <uri>model://movo_description/meshes/manipulation/robotiq/visual/robotiq_85_knuckle_link.obj</uri>
          </mesh>
        </geometry>
      </visual>
      <visual name='gripper_finger2_knuckle_link_fixed_joint_lump__gripper_finger2_finger_link_visual_1'>
        <pose>-0.004086 -0.031486 0 0 -0 0</pose>
        <geometry>
          <mesh>
            <scale>1 1 1</scale>
            <uri>model://movo_description/meshes/manipulation/robotiq/visual/robotiq_85_finger_link.obj</uri>
          </mesh>
        </geometry>
      </visual>
    </link>
  </model>
</sdf>
