<sdf version='1.7'>
  <model name='robotiq_arg2f_140_model'>
    <link name='robotiq_arg2f_base_link'>
      <inertial>
        <pose>0 -5e-06 0.03145 0 -0 0</pose>
        <mass>0.22652</mass>
        <inertia>
          <ixx>0.00020005</ixx>
          <ixy>-4.2442e-10</ixy>
          <ixz>-2.9069e-10</ixz>
          <iyy>0.00017832</iyy>
          <iyz>-3.4402e-08</iyz>
          <izz>0.00013478</izz>
        </inertia>
      </inertial>
      <collision name='robotiq_arg2f_base_link_collision'>
        <pose>0 0 0 0 -0 0</pose>
        <geometry>
          <mesh>
            <scale>1 1 1</scale>
            <uri>/home/dan/Projects/Pydrake-robotiq140/catkin_ws/src/robotiq/robotiq_2f_140_gripper_visualization/meshes/collision/robotiq_arg2f_base_link.obj</uri>
          </mesh>
        </geometry>
      </collision>
      <visual name='robotiq_arg2f_base_link_visual'>
        <pose>0 0 0 0 -0 0</pose>
        <geometry>
          <mesh>
            <scale>1 1 1</scale>
            <uri>/home/dan/Projects/Pydrake-robotiq140/catkin_ws/src/robotiq/robotiq_2f_140_gripper_visualization/meshes/visual/robotiq_arg2f_base_link.obj</uri>
          </mesh>
        </geometry>
      </visual>
    </link>
    <joint name='finger_joint' type='revolute'>
      <pose relative_to='robotiq_arg2f_base_link'>0 -0.030601 0.054905 2.2958 -0 0</pose>
      <parent>robotiq_arg2f_base_link</parent>
      <child>left_outer_knuckle</child>
      <axis>
        <xyz>-1 0 0</xyz>
        <limit>
          <lower>0</lower>
          <upper>0.7</upper>
          <effort>1000</effort>
          <velocity>2</velocity>
        </limit>
        <dynamics>
          <spring_reference>0</spring_reference>
          <spring_stiffness>0</spring_stiffness>
        </dynamics>
      </axis>
    </joint>
    <link name='left_outer_knuckle'>
      <pose relative_to='finger_joint'>0 0 0 0 -0 0</pose>
      <inertial>
        <pose>0.000164 0.04584 0.01178 0 -0 0</pose>
        <mass>0.0311462</mass>
        <inertia>
          <ixx>2.96016e-05</ixx>
          <ixy>-1.09755e-07</ixy>
          <ixz>7.40449e-08</ixz>
          <iyy>1.16215e-05</iyy>
          <iyz>1.08762e-05</iyz>
          <izz>2.07508e-05</izz>
        </inertia>
      </inertial>
      <collision name='left_outer_knuckle_collision'>
        <pose>0 0 0 0 -0 0</pose>
        <geometry>
          <mesh>
            <scale>1 1 1</scale>
            <uri>/home/dan/Projects/Pydrake-robotiq140/catkin_ws/src/robotiq/robotiq_2f_140_gripper_visualization/meshes/collision/robotiq_arg2f_140_outer_knuckle.obj</uri>
          </mesh>
        </geometry>
      </collision>
      <collision name='left_outer_knuckle_fixed_joint_lump__left_outer_finger_collision_1'>
        <pose>0 0.01822 0.026002 0 -0 0</pose>
        <geometry>
          <mesh>
            <scale>1 1 1</scale>
            <uri>/home/dan/Projects/Pydrake-robotiq140/catkin_ws/src/robotiq/robotiq_2f_140_gripper_visualization/meshes/collision/robotiq_arg2f_140_outer_finger.obj</uri>
          </mesh>
        </geometry>
      </collision>
      <visual name='left_outer_knuckle_visual'>
        <pose>0 0 0 0 -0 0</pose>
        <geometry>
          <mesh>
            <scale>1 1 1</scale>
            <uri>/home/dan/Projects/Pydrake-robotiq140/catkin_ws/src/robotiq/robotiq_2f_140_gripper_visualization/meshes/visual/robotiq_arg2f_140_outer_knuckle.obj</uri>
          </mesh>
        </geometry>
      </visual>
      <visual name='left_outer_knuckle_fixed_joint_lump__left_outer_finger_visual_1'>
        <pose>0 0.01822 0.026002 0 -0 0</pose>
        <geometry>
          <mesh>
            <scale>1 1 1</scale>
            <uri>/home/dan/Projects/Pydrake-robotiq140/catkin_ws/src/robotiq/robotiq_2f_140_gripper_visualization/meshes/visual/robotiq_arg2f_140_outer_finger.obj</uri>
          </mesh>
        </geometry>
      </visual>
    </link>
    <joint name='left_inner_finger_joint' type='revolute'>
      <pose relative_to='left_outer_knuckle'>0 0.099975 -0.002219 -0.725 0 0</pose>
      <parent>left_outer_knuckle</parent>
      <child>left_inner_finger</child>
      <axis>
        <xyz>1 0 0</xyz>
        <limit>
          <lower>-0.8757</lower>
          <upper>0.8757</upper>
          <effort>1000</effort>
          <velocity>2</velocity>
        </limit>
        <dynamics>
          <spring_reference>0</spring_reference>
          <spring_stiffness>0</spring_stiffness>
        </dynamics>
      </axis>
    </joint>
    <link name='left_inner_finger'>
      <pose relative_to='left_inner_finger_joint'>0 0 0 0 -0 0</pose>
      <inertial>
        <pose>0.0003 0.016008 -0.013695 0 -0 0</pose>
        <mass>0.0104003</mass>
        <inertia>
          <ixx>2.71909e-06</ixx>
          <ixy>1.35402e-21</ixy>
          <ixz>-7.18173e-22</ixz>
          <iyy>7.691e-07</iyy>
          <iyz>6.74715e-07</iyz>
          <izz>2.30315e-06</izz>
        </inertia>
      </inertial>
      <collision name='left_inner_finger_collision'>
        <pose>0 0 0 0 -0 0</pose>
        <geometry>
          <mesh>
            <scale>1 1 1</scale>
            <uri>/home/dan/Projects/Pydrake-robotiq140/catkin_ws/src/robotiq/robotiq_2f_140_gripper_visualization/meshes/collision/robotiq_arg2f_140_inner_finger.obj</uri>
          </mesh>
        </geometry>
      </collision>
      <collision name='left_inner_finger_pad_collision_1'>
        <pose>0 0.045755 -0.02722 0 -0 0</pose>
        <geometry>
          <box>
            <size>0.03 0.07 0.0075</size>
          </box>
        </geometry>
      </collision>
      <visual name='left_inner_finger_visual'>
        <pose>0 0 0 0 -0 0</pose>
        <geometry>
          <mesh>
            <scale>1 1 1</scale>
            <uri>/home/dan/Projects/Pydrake-robotiq140/catkin_ws/src/robotiq/robotiq_2f_140_gripper_visualization/meshes/visual/robotiq_arg2f_140_inner_finger.obj</uri>
          </mesh>
        </geometry>
      </visual>
      <visual name='left_inner_finger_pad_visual_1'>
        <pose>0 0.045755 -0.02722 0 -0 0</pose>
        <geometry>
          <box>
            <size>0.027 0.065 0.0075</size>
          </box>
        </geometry>
      </visual>
    </link>
    <joint name='left_inner_knuckle_joint' type='revolute'>
      <pose relative_to='robotiq_arg2f_base_link'>0 -0.0127 0.06142 2.2958 -0 0</pose>
      <parent>robotiq_arg2f_base_link</parent>
      <child>left_inner_knuckle</child>
      <axis>
        <xyz>1 0 0</xyz>
        <limit>
          <lower>-0.8757</lower>
          <upper>0.8757</upper>
          <effort>1000</effort>
          <velocity>2</velocity>
        </limit>
        <dynamics>
          <spring_reference>0</spring_reference>
          <spring_stiffness>0</spring_stiffness>
        </dynamics>
      </axis>
    </joint>
    <link name='left_inner_knuckle'>
      <pose relative_to='left_inner_knuckle_joint'>0 0 0 0 -0 0</pose>
      <inertial>
        <pose>0.000123 0.050785 0.00104 0 -0 0</pose>
        <mass>0.0271177</mass>
        <inertia>
          <ixx>2.6191e-05</ixx>
          <ixy>-2.43617e-07</ixy>
          <ixz>-6.3779e-09</ixz>
          <iyy>2.82702e-06</iyy>
          <iyz>-5.37201e-07</iyz>
          <izz>2.83696e-05</izz>
        </inertia>
      </inertial>
      <collision name='left_inner_knuckle_collision'>
        <pose>0 0 0 0 -0 0</pose>
        <geometry>
          <mesh>
            <scale>1 1 1</scale>
            <uri>/home/dan/Projects/Pydrake-robotiq140/catkin_ws/src/robotiq/robotiq_2f_140_gripper_visualization/meshes/collision/robotiq_arg2f_140_inner_knuckle.obj</uri>
          </mesh>
        </geometry>
      </collision>
      <visual name='left_inner_knuckle_visual'>
        <pose>0 0 0 0 -0 0</pose>
        <geometry>
          <mesh>
            <scale>1 1 1</scale>
            <uri>/home/dan/Projects/Pydrake-robotiq140/catkin_ws/src/robotiq/robotiq_2f_140_gripper_visualization/meshes/visual/robotiq_arg2f_140_inner_knuckle.obj</uri>
          </mesh>
        </geometry>
      </visual>
    </link>
    <joint name='right_inner_knuckle_joint' type='revolute'>
      <pose relative_to='robotiq_arg2f_base_link'>0 0.0127 0.06142 2.2958 -0 3.14159</pose>
      <parent>robotiq_arg2f_base_link</parent>
      <child>right_inner_knuckle</child>
      <axis>
        <xyz>1 0 0</xyz>
        <limit>
          <lower>-0.8757</lower>
          <upper>0.8757</upper>
          <effort>1000</effort>
          <velocity>2</velocity>
        </limit>
        <dynamics>
          <spring_reference>0</spring_reference>
          <spring_stiffness>0</spring_stiffness>
        </dynamics>
      </axis>
    </joint>
    <link name='right_inner_knuckle'>
      <pose relative_to='right_inner_knuckle_joint'>0 0 0 0 -0 0</pose>
      <inertial>
        <pose>0.000123 0.050785 0.00104 0 -0 0</pose>
        <mass>0.0271177</mass>
        <inertia>
          <ixx>2.6191e-05</ixx>
          <ixy>-2.43617e-07</ixy>
          <ixz>-6.3779e-09</ixz>
          <iyy>2.82702e-06</iyy>
          <iyz>-5.37201e-07</iyz>
          <izz>2.83696e-05</izz>
        </inertia>
      </inertial>
      <collision name='right_inner_knuckle_collision'>
        <pose>0 0 0 0 -0 0</pose>
        <geometry>
          <mesh>
            <scale>1 1 1</scale>
            <uri>/home/dan/Projects/Pydrake-robotiq140/catkin_ws/src/robotiq/robotiq_2f_140_gripper_visualization/meshes/collision/robotiq_arg2f_140_inner_knuckle.obj</uri>
          </mesh>
        </geometry>
      </collision>
      <visual name='right_inner_knuckle_visual'>
        <pose>0 0 0 0 -0 0</pose>
        <geometry>
          <mesh>
            <scale>1 1 1</scale>
            <uri>/home/dan/Projects/Pydrake-robotiq140/catkin_ws/src/robotiq/robotiq_2f_140_gripper_visualization/meshes/visual/robotiq_arg2f_140_inner_knuckle.obj</uri>
          </mesh>
        </geometry>
      </visual>
    </link>
    <joint name='right_outer_knuckle_joint' type='revolute'>
      <pose relative_to='robotiq_arg2f_base_link'>0 0.030601 0.054905 2.2958 -0 -3.14159</pose>
      <parent>robotiq_arg2f_base_link</parent>
      <child>right_outer_knuckle</child>
      <axis>
        <xyz>1 0 0</xyz>
        <limit>
          <lower>-0.725</lower>
          <upper>0.725</upper>
          <effort>1000</effort>
          <velocity>2</velocity>
        </limit>
        <dynamics>
          <spring_reference>0</spring_reference>
          <spring_stiffness>0</spring_stiffness>
        </dynamics>
      </axis>
    </joint>
    <link name='right_outer_knuckle'>
      <pose relative_to='right_outer_knuckle_joint'>0 0 0 0 -0 0</pose>
      <inertial>
        <pose>0.000164 0.04584 0.01178 0 -0 0</pose>
        <mass>0.0311462</mass>
        <inertia>
          <ixx>2.96016e-05</ixx>
          <ixy>-1.09755e-07</ixy>
          <ixz>7.40449e-08</ixz>
          <iyy>1.16215e-05</iyy>
          <iyz>1.08762e-05</iyz>
          <izz>2.07508e-05</izz>
        </inertia>
      </inertial>
      <collision name='right_outer_knuckle_collision'>
        <pose>0 0 0 0 -0 0</pose>
        <geometry>
          <mesh>
            <scale>1 1 1</scale>
            <uri>/home/dan/Projects/Pydrake-robotiq140/catkin_ws/src/robotiq/robotiq_2f_140_gripper_visualization/meshes/collision/robotiq_arg2f_140_outer_knuckle.obj</uri>
          </mesh>
        </geometry>
      </collision>
      <collision name='right_outer_knuckle_fixed_joint_lump__right_outer_finger_collision_1'>
        <pose>0 0.01822 0.026002 0 -0 0</pose>
        <geometry>
          <mesh>
            <scale>1 1 1</scale>
            <uri>/home/dan/Projects/Pydrake-robotiq140/catkin_ws/src/robotiq/robotiq_2f_140_gripper_visualization/meshes/collision/robotiq_arg2f_140_outer_finger.obj</uri>
          </mesh>
        </geometry>
      </collision>
      <visual name='right_outer_knuckle_visual'>
        <pose>0 0 0 0 -0 0</pose>
        <geometry>
          <mesh>
            <scale>1 1 1</scale>
            <uri>/home/dan/Projects/Pydrake-robotiq140/catkin_ws/src/robotiq/robotiq_2f_140_gripper_visualization/meshes/visual/robotiq_arg2f_140_outer_knuckle.obj</uri>
          </mesh>
        </geometry>
      </visual>
      <visual name='right_outer_knuckle_fixed_joint_lump__right_outer_finger_visual_1'>
        <pose>0 0.01822 0.026002 0 -0 0</pose>
        <geometry>
          <mesh>
            <scale>1 1 1</scale>
            <uri>/home/dan/Projects/Pydrake-robotiq140/catkin_ws/src/robotiq/robotiq_2f_140_gripper_visualization/meshes/visual/robotiq_arg2f_140_outer_finger.obj</uri>
          </mesh>
        </geometry>
      </visual>
    </link>
    <joint name='right_inner_finger_joint' type='revolute'>
      <pose relative_to='right_outer_knuckle'>0 0.099975 -0.002219 -0.725 0 0</pose>
      <parent>right_outer_knuckle</parent>
      <child>right_inner_finger</child>
      <axis>
        <xyz>1 0 0</xyz>
        <limit>
          <lower>-0.8757</lower>
          <upper>0.8757</upper>
          <effort>1000</effort>
          <velocity>2</velocity>
        </limit>
        <dynamics>
          <spring_reference>0</spring_reference>
          <spring_stiffness>0</spring_stiffness>
        </dynamics>
      </axis>
    </joint>
    <link name='right_inner_finger'>
      <pose relative_to='right_inner_finger_joint'>0 0 0 0 -0 0</pose>
      <inertial>
        <pose>0.0003 0.016008 -0.013695 0 -0 0</pose>
        <mass>0.0104003</mass>
        <inertia>
          <ixx>2.71909e-06</ixx>
          <ixy>1.35402e-21</ixy>
          <ixz>-7.18173e-22</ixz>
          <iyy>7.691e-07</iyy>
          <iyz>6.74715e-07</iyz>
          <izz>2.30315e-06</izz>
        </inertia>
      </inertial>
      <collision name='right_inner_finger_collision'>
        <pose>0 0 0 0 -0 0</pose>
        <geometry>
          <mesh>
            <scale>1 1 1</scale>
            <uri>/home/dan/Projects/Pydrake-robotiq140/catkin_ws/src/robotiq/robotiq_2f_140_gripper_visualization/meshes/collision/robotiq_arg2f_140_inner_finger.obj</uri>
          </mesh>
        </geometry>
      </collision>
      <collision name='right_inner_finger_pad_collision_1'>
        <pose>0 0.045755 -0.02722 0 -0 0</pose>
        <geometry>
          <box>
            <size>0.03 0.07 0.0075</size>
          </box>
        </geometry>
      </collision>
      <visual name='right_inner_finger_visual'>
        <pose>0 0 0 0 -0 0</pose>
        <geometry>
          <mesh>
            <scale>1 1 1</scale>
            <uri>/home/dan/Projects/Pydrake-robotiq140/catkin_ws/src/robotiq/robotiq_2f_140_gripper_visualization/meshes/visual/robotiq_arg2f_140_inner_finger.obj</uri>
          </mesh>
        </geometry>
      </visual>
      <visual name='right_inner_finger_pad_visual_1'>
        <pose>0 0.045755 -0.02722 0 -0 0</pose>
        <geometry>
          <box>
            <size>0.027 0.065 0.0075</size>
          </box>
        </geometry>
      </visual>
    </link>
  </model>
</sdf>
